_단순히 빨간줄 떴다고 try-catch 붙이는 걸 넘어서 베이스를 다져보자._

- 자바에서는 상속을 이용해서 모든 예외를 표현합니다. 모든 예외 클래스는 Throwable의 자손 클래스 입니다.
- `Throwable` 에는 크게 두 종류의 자식 클래스가 있습니다.
    - `Error` 는 프로그램이 종료되어야 하는 심각한 문제를 표현합니다. 대부분 컴퓨터나 JVM이 시스템적으로 동작할 수 없는 상황을 표현합니다.

        Java는 JVM내의 Heap이라는 메모리 공간을 운영체제로부터 할당 받아 사용합니다. 할당 받을 수 있는 최대 메모리 이상을 사용하면, JVM이 다운될 수 밖에 없습니다. 이 경우 `OutOfMemoryError`가 나면서 프로그램이 종료됩니다. 자바의 대표적인 에러 상황으로 줄여서 `OOM`이라고도 합니다.

    - `Exception` 은 프로그램이 종료되지는 않지만 예외나 문제상황을 표현하기 위해 사용합니다.
- 자바에 미리 정의 되어있는 예외 클래스 들이 있습니다. 기본적으로 이미 있는 것을 사용하시되, 필요한 것으로 표현할 수 없거나 구체적인 목적을 가진 예외를 정의하고 싶다면, `Throwable` 또는 그 하위에 있는 예외 클래스를 상속받아서 자신만의 예외 클래스를 정의할 수 있습니다.
*(아래 사진은 자바의 기본 예외 클래스들 중 대표적인 것들의 상속 관계도 입니다.)*

<figure>
    <img src="https://media.vlpt.us/images/codepark_kr/post/a70025be-d97d-4ba4-81de-bf9b8fe48d2b/ExceptionClassHierarchy.png">
</figure>

- 여러분이 표현하려는 예외 상황은 대부분 `Exception` 종류일 것입니다.
- 실행도중 발생하는 Exception은 `RuntimeException`을 상속받아서 정의하세요.
- 파일을 읽고 쓰거나, 원격에 있는 저장소로부터 데이터를 읽고 쓸 때 나는 에러를 표현하려면 `IOException`을 상속받아서 정의하세요.

<details markdown="1">
<summary> try-catch 펼치기 </summary>

```java
try {
    // 예외가 발생할 가능성이 있는 코드를 구현합니다.
} catch (FileNotFoundException e) {
    // FileNotFoundException이 발생했을 경우,이를 처리하기 위한 코드를 구현합니다.
} catch (IOException e) {
    // FileNotFoundException이 아닌 IOException이 발생했을 경우,이를 처리하기 위한 코드를 구현합니다.
} finally {
    // 예외의 발생여부에 관계없이 항상 수행되어야하는 코드를 구현합니다.
}
```

`finally` 구문은 필수는 아닙니다.

만약, 예외가 발생하지 않는다면 try → finally 순으로 실행됩니다. 

또한, 예외는 중복 catch 블럭을 사용하여 다양한 예외처리를 수행할 수 있습니다. 중복 catch블럭을 사용할 때는 먼저 선언된 catch블럭부터 확인합니다. 앞의 catch블럭에서 잡혔다면, 뒤의 catch블럭으로는 전파되지 않습니다. 좁은 범위의 예외부터 앞에 선언하는 것이 좋습니다. 여기서 좁은 범위란 상속관계에서 자식 클래스에 위치 할수록 좁은 범위입니다. 예를 들어서 `IOException`이 발생할 것 같아 예외처리를 하고, 그 외의 예외도 예외처리를 하고 싶다면 `IOException`을 catch 하는 구문을 먼저, `Exception` 을 catch하는 구문을 그 뒤에 작성합니다.

- **[코드스니펫] try-catch-finally 예제 - Main 함수**

    ```java
    public class Main {
        public static void main(String[] args) {
            
        }
    }
    ```

```java
public class Main {
    public static void main(String[] args) {
        int number = 10;
        int result;

        for (int i = 10; i >= 0; i--) {
            try {
                result = number / i;
                System.out.println(result);
            } catch (Exception e) {
                System.out.println("Exception발생: " + e.getMessage());
            } finally {
                System.out.println("항상 실행되는 finally 구문");
            }
        }
    }

}
```

0으로 나눠지는 경우 catch문이 실행되는 예제입니다. 출력 결과를 보면서 try - catch - finally 구조를 이해해보도록 하세요!

</details>
        
        
        
근데, try-with-resource란 게 있는데 특별한 건 아니고, 트라이캐치랑 거의 비슷한데,
try괄호()안에 **Closable 인터페이스를 구현한 객체** 를 선언하면 사용됨. 보통 스트림사용할때 편하게 하려는 것임.

<details markdown="1">
<summary>try-with-resource 펼치기</summary>

- try-catch문이외에 try-with-resource문도 존재합니다.
- 입출력과 함께 자주 쓰이는 구문입니다! 일반적으로 사용되었던 자원을 끝난 후에 닫아줘야 하는 것들이 존재하는데 여기서 try-catch-finally구문보다 편리한 것이 지금부터 설명드릴 **try-with-resource** 문입니다! **(입출력에 대해서는 추후 배울 것이므로 지금은, *"입력과 출력에 대한 것이구나"*라고 생각하시면 됩니다.)**
- 기존의 try-catch(-finally)문은 자원을 닫을 때 close()를 사용해야 합니다.
- try-with-resource문은 try문을 벗어나는 순간 자동적으로 close()가 호출됩니다.
- 어떻게 사용하면 될까요?
→ try()안의 입출력 스트림을 생성하는 로직을 작성할 때 해당 객체가 AutoClosable 인터페이스를 구현한 객체여야 합니다.

    ```java
    import java.io.FileOutputStream;
    import java.io.IOException;

    public class Main {
        public static void main(String[] args) {

            try (FileOutputStream out = new FileOutputStream("test.txt")) {
                // test.txt file 에 Hello Sparta 를 출력
                out.write("Hello Sparta".getBytes());
                out.flush();
            } catch (IOException e) {
                e.printStackTrace();
            }
        }
    }
    ```

    → 이처럼 형식은 try-catch문과 비슷하지만, try()안에 AutoClosable 인터페이스를 구현한 객체를 선언하면 사용할 수 있습니다! 간단하지만, 매우 유용한 예외형식이죠!

    AutoClosable 인터페이스
    그럼 왜 AutoClosable 인터페이스를 사용해야할까요??바로 AutoClosable 인터페이스에는 예외가 발생할 경우 close()메소드를 호출하기로 정의되어있기 때문입니다.

- _만약에 try-with-resource가 아니라 일반 try catch문을 사용했다면_
-  아래와 같은 코드가 됩니다. 코드가 길어질 뿐만 아니라 `FileOutputStream` 을 열고 닫을때 생기는 `Exception` 까지 그 상위에서 catch를 하거나 `throws`로 감싸줘야합니다.

    ```java
    import java.io.FileOutputStream;
    import java.io.IOException;

    public class Main {
        public static void main(String[] args) throws IOException {
            FileOutputStream out = new FileOutputStream("test.txt");
            try {
                // test.txt file 에 Hello Sparta 를 출력
                out.write("Hello Sparta".getBytes());
                out.flush();
            } catch (IOException e) {
                e.printStackTrace();
            }
            out.close();
        }
    }
    ```

</details>

### 메소드에서의 예외 선언
- catch문을 이용해서 예외처리를 하지 않은 경우, 메소드에 throws로 예외가 발생할 수 있다는 것을 알려주어야 합니다. throws 키워드가 있는 함수를 호출한다면, caller 쪽에서 catch와 관련된 코드를 작성해주어야 합니다.
    
```java
void method() throws IndexOutOfBoundsException, IllegalArgumentException {
		//메소드의 내용
}
```

 → 이처럼, 키워드 throws를 사용해서 메소드 내에서 발생할 수 있는 예외를 적어주면 됩니다!
  
## 퀴즈로 보는 메소드 예외선언 예시
<details markdown="1">
<summary>문제 상황</summary>

다음 스니펫에 있는 `divide()` 함수는 매개변수(parameter)에 들어오는 값에 따라서 `ArithmeticException`과 `ArrayIndexOutOfBoundsException`이 발생할 수 있습니다.

1. throws 키워드를 통해서 divide() 함수에서 발생할 수 있는 exception의 종류가 무엇인지 알게 해주세요.
2. Main 함수에서 try-catch 문을 이용해서, 다음 동작을 구현하세요.
    1. `ArithmeticException`이 발생할 때는 잘못된 계산임을 알리는 문구를 출력하세요.
    2. `ArrayIndexOutOfBoundsException`이 발생할 때는 현재 배열의 index범위를 알려주는 문구를 출력하세요.
- **[코드스니펫] 예외처리 퀴즈 - Main 함수**

    ```java
    class ArrayCalculation {

        int[] arr = { 0, 1, 2, 3, 4 };

        public int divide(int denominatorIndex, int numeratorIndex) {
            return arr[denominatorIndex] / arr[numeratorIndex];
        }
    }

    public class Main {
        public static void main(String[] args) {
            ArrayCalculation arrayCalculation = new ArrayCalculation();

            System.out.println("2 / 1 = " + arrayCalculation.divide(2, 1));
            System.out.println("1 / 0 = " + arrayCalculation.divide(1, 0)); // java.lang.ArithmeticException: "/ by zero"
            System.out.println("Try to divide using out of index element = "
                               + arrayCalculation.divide(5, 0)); // java.lang.ArrayIndexOutOfBoundsException: 5
        }

    }
    ```

</details>

<details markdown="1">
<summary>정답</summary>

```java
class ArrayCalculation {

    int[] arr = { 0, 1, 2, 3, 4 };

    public int divide(int denominatorIndex, int numeratorIndex)
            throws ArithmeticException, ArrayIndexOutOfBoundsException {
        return arr[denominatorIndex] / arr[numeratorIndex];
    }
}

public class Main {
    public static void main(String[] args) {
        ArrayCalculation arrayCalculation = new ArrayCalculation();

				System.out.println("2 / 1 = " + arrayCalculation.divide(2, 1));
        try {
            System.out.println(
                    "1 / 0 = " + arrayCalculation.divide(1, 0));
        } catch (ArithmeticException arithmeticException) {
            System.out.println("잘못된 계산입니다. " + arithmeticException.getMessage());
        }
        try {
            System.out.println("Try to divide using out of index element = "
                               + arrayCalculation.divide(5, 0)); 
        } catch (ArrayIndexOutOfBoundsException arrayIndexOutOfBoundsException) {
            System.out.println(
                    "잘못된 index 범위로 나누었습니다. 타당 index 범위는 0부터" + (arrayCalculation.arr.length - 1) + "까지 입니다.");
        }
    }

}
```

</details>
